Workbook

Sheet diesel used
A1: စက်သုံးဆီဆိုင်မဟုတ်သည့် အခြားကဏ္ဍများ အရေးပေါ်စက်သုံးဆီလိုအပ်ချက်များ တင်ပြခြင်း
A2: စဥ် | B2: Center Name | C2: Type (Regular/ LNG) | D2: ဆီအမျိုးအစား (PD/HSD) | E2: ဝယ်ယူခဲ့ သည့် ကုမ္ပဏီ | F2: Machine Power | G2: Consumpiton Per Hour | H2: 46106 | M2: 46107 | R2: 46108 | W2: 46109 | AB2: 46110
D3: မသိရင် မဖြည့်လဲရပါသည် | E3: မသိရင် မဖြည့်လဲရပါသည် | F3: KVA | G3: Liter | H3: Generator Run Hr | I3: Daily Used (L) | J3: Spare Tank+Drum Balance (L) | K3: Blackout Hr (Gen 1 လုံးထက်ပိုသူများသာဖြည့်ရန်) | M3: Generator Run Hr | N3: Daily Used (L) | O3: Spare Tank+Drum Balance (L) | P3: Blackout Hr (Gen 1 လုံးထက်ပိုသူများသာဖြည့်ရန်) | R3: Generator Run Hr | S3: Daily Used (L) | T3: Spare Tank+Drum Balance (L) | U3: Blackout Hr (Gen 1 လုံးထက်ပိုသူများသာဖြည့်ရန်) | W3: Generator Run Hr | X3: Daily Used (L) | Y3: Spare Tank+Drum Balance (L) | Z3: Blackout Hr (Gen 1 လုံးထက်ပိုသူများသာဖြည့်ရန်) | AB3: Generator Run Hr | AC3: Daily Used (L) | AD3: Spare Tank+Drum Balance (L) | AE3: Blackout Hr (Gen 1 လုံးထက်ပိုသူများသာဖြည့်ရန်)
A4: ALL Total | H4: =SUM(H8:H60) -> 70.306667 | I4: =SUM(I8:I60) -> 3099.624 | J4: =SUM(J8:J60) -> 108786.81 | K4: =SUM(K8:K60) -> 0 | M4: =SUM(M8:M60) -> 88.443333 | N4: =SUM(N8:N60) -> 3743.306 | O4: =SUM(O8:O60) -> 109298.62 | P4: =SUM(P8:P60) -> 0 | R4: =SUM(R8:R60) -> 67.27 | S4: =SUM(S8:S60) -> 2335.81 | T4: =SUM(T8:T60) -> 111773.36 | U4: =SUM(U8:U60) -> 0 | W4: =SUM(W8:W60) -> 126.1075 | X4: =SUM(X8:X60) -> 5129.414 | Y4: =SUM(Y8:Y60) -> 107605.8 | Z4: =SUM(Z8:Z60) -> 5614 | AB4: =SUM(AB8:AB60) -> 82.14 | AC4: =SUM(AC8:AC60) -> 2340.082 | AD4: =SUM(AD8:AD60) -> 101978.83 | AE4: =SUM(AE8:AE60) -> 0
A6: နေ့စဥ် မနက်၉နာရီမခွဲခင် အပြီးဝင်ဖြည့်ပေးပါရန် | H6: *Generator run hour ကို နာရီပြောင်းပြီး ဖြည့်ပေးပါ။ ဥပမာ။ 5:15 ဆိုရင် 5+(15/60)= 5.25 Hr
H7: * spare tank balalce ကို site တစ်ခုအတွက် spare tank+drum အားလုံးစုစုပေါင်းပြီး တစ်ကြောင်းဘဲဖြည့်ပေးပါ။ Genrrator တစ်လုံးထက်ပိုသော site များအတွက် ကြိုက်ရာ generator တစ်ခု၏ဘေးတွင်ရေးပေးပါ။
A8: 1 | B8: CM19 | C8: Regular | F8: KOHLER-550 | G8: 75 | H8: =2+(16/60) -> 2.2666667 | I8: 105 | J8: 2924 | M8: =3+(19/60) -> 3.3166667 | N8: 160 | O8: 2661 | R8: 0 | S8: 0 | T8: 4566 | W8: =1+(10/60) -> 1.1666667 | X8: 51 | Y8: 5515 | AB8: =4+(0/60) -> 4 | AC8: 185 | AD8: 5330
A9: 2 | B9: CM19 | C9: Regular | F9: POWER MAX-150 | G9: 30 | H9: =2+(0/60) -> 2 | M9: =8+(0/60) -> 8 | N9: 103 | R9: =4+(0/60) -> 4 | S9: 95 | W9: 0 | X9: 0 | AB9: 0 | AC9: 0
A10: 3 | B10: CM19 | C10: Regular | F10: HIMOINSA-300 | G10: 40 | H10: 0 | I10: 0 | J10: 0 | M10: 0 | N10: 0 | R10: 0 | S10: 0 | W10: 0 | X10: 0 | AB10: 0 | AC10: 0
A11: 4 | B11: CMAYW | C11: Regular | F11: KOHLER-440 | G11: 60 | H11: =1+(7/60) -> 1.1166667 | I11: 22 | J11: 2146 | M11: =4+(22/60) -> 4.3666667 | N11: 192 | O11: 2954 | R11: =4+(7/30) -> 4.2333333 | S11: 90 | T11: 2864 | W11: =8+(60/60) -> 9 | X11: 378 | Y11: 2486 | AB11: =7+(28/60) -> 7.4666667 | AC11: 159 | AD11: 2327
A12: 5 | B12: CMDGSK | C12: Regular | F12: KOHLER-550 | G12: 70 | H12: 7.4 | I12: 309 | J12: 6809 | M12: 8.18 | N12: 373 | O12: 6418 | R12: 11.76 | S12: 418 | T12: 6100 | W12: 8.05 | X12: 386 | Y12: 5786 | Z12: 5614 | AB12: 8.42 | AC12: 205 | AD12: 5409
A13: 6 | B13: CMKSM | C13: Regular | F13: AKSA-100 | G13: 13 | H13: 0 | I13: 0 | M13: =24/60 -> 0.4 | N13: 4.546 | O13: 3041.01 | R13: 0 | S13: 0 | T13: 2995.55 | W13: =1+(52/60) -> 1.8666667 | X13: 18.184 | Y13: 2927.36 | AB13: =2+(8/60) -> 2.1333333 | AC13: 13.638 | AD13: 2872.808
A14: 7 | B14: CMKSM | C14: Regular | F14: KOHLER-350 | G14: 55 | R14: 0 | S14: 0 | W14: 0 | AB14: 0 | AC14: 0
A15: 8 | B15: CMKSM | C15: Regular | F15: LONGEN-275 | G15: 45.46 | H15: 0 | I15: 0 | J15: 3041.01 | M15: =2+(45/60) -> 2.75 | N15: 40.914 | R15: 0 | S15: 0 | W15: =1+(53/60) -> 1.8833333 | X15: 50.006 | AB15: =3+(26/60) -> 3.4333333 | AC15: 40.914
A16: 9 | B16: CMLNP | C16: Regular | F16: POWER MAX-500 | G16: 69 | H16: 0 | I16: 0 | J16: 3145.712 | M16: =2+(8/60) -> 2.1333333 | N16: 109.104 | O16: 5027.636 | R16: 0 | S16: 0 | T16: 5027.636 | W16: 0 | X16: 0 | Y16: 5027.636 | AB16: 0 | AC16: 0 | AD16: 5027.636
A17: 10 | B17: CMLNP | C17: Regular | F17: POWER MAX-500 | G17: 69 | H17: 0 | I17: 0 | M17: =2+(8/60) -> 2.1333333 | N17: 108.972 | R17: 0 | S17: 0 | W17: 0 | X17: 0 | AB17: 0 | AC17: 0
A18: 12 | B18: CMLPZD | C18: Regular | F18: POWER MAX-500 | G18: 70 | H18: =3+(1/60) -> 3.0166667 | I18: 182 | J18: 4501 | M18: =2+(58/60) -> 2.9666667 | N18: 141 | O18: 4700 | R18: =0+(50/60) -> 0.83333333 | S18: 45 | T18: 4610 | W18: =9+(30/60) -> 9.5 | X18: 395 | Y18: 4182 | AB18: =5+(13/60) -> 5.2166667 | AC18: 164 | AD18: 3787
A19: 11 | B19: CMLPZD | C19: Regular | F19: KOHLER MOBILE-550 | G19: 68 | H19: =3+(0/60) -> 3 | I19: 114 | J19: 4387 | M19: =1+(11/60) -> 1.1833333 | N19: 45 | O19: 4655 | R19: =0+(56/60) -> 0.93333333 | S19: 33 | T19: 4577 | W19: =4+(1/60) -> 4.0166667 | X19: 182 | Y19: 4000 | AB19: =1+(11/60) -> 1.1833333 | AC19: 49
A20: 13 | B20: CMLPZD | C20: Regular | F20: SDMO G3-700 | G20: 86 | H20: 0 | I20: 0 | J20: 0 | M20: 0 | N20: 0 | O20: 0 | R20: 0 | S20: 0 | W20: 0 | X20: 0
A21: 14 | B21: CMLSPL | C21: Regular | F21: HIMONISA-200 | G21: 18.184 | H21: 0 | I21: 0 | M21: 0 | N21: 0 | T21: 5041 | W21: =4+(23/60) -> 4.3833333 | X21: 73 | Y21: 3858 | AB21: =6+(17/60) -> 6.2833333 | AC21: 103 | AD21: 3755
A22: 15 | B22: CMLSPL | C22: Regular | F22: KOHLER-727 | G22: 90.92 | H22: =4+(26/60) -> 4.4333333 | I22: 318 | M22: =2+(55/60) -> 2.9166667 | N22: 227 | R22: =2+(43/60) -> 2.7166667 | S22: 173 | W22: =8+(45/60) -> 8.75 | X22: 641 | AB22: 0 | AC22: 0
A23: 16 | B23: CMLSPL | C23: Regular | F23: POWER MAX-500 | G23: 77.282 | H23: =4+(28/60) -> 4.4666667 | I23: 209 | J23: 4723 | M23: =2+(57/60) -> 2.95 | N23: 159 | O23: 5337 | R23: =2+(44/60) -> 2.7333333 | S23: 123 | W23: =8+(58/60) -> 8.9666667 | X23: 469 | AB23: 0 | AC23: 0
A24: 17 | B24: CMMNG | C24: Regular | F24: HARMONY-700 | G24: 18 | H24: =2+(40/60) -> 2.6666667 | I24: 136.308 | J24: 2627.42 | M24: =1+(7/60) -> 1.1166667 | N24: 72.736 | O24: 2554.684 | R24: 0 | S24: 0 | T24: 2554.684 | W24: =2+(13/60) -> 2.2166667 | X24: 113.65 | Y24: 2441.034 | AB24: 0 | AC24: 0 | AD24: 2441.034
A25: 18 | B25: CMPale | C25: Regular | F25: KOHLER-220 | G25: 22 | H25: 4.03 | I25: 105 | J25: 1912.5 | M25: 4.09 | N25: 107.5 | O25: 1650 | R25: 0 | S25: 0 | T25: 2650 | W25: 4.54 | X25: 112.5 | Y25: 2425 | AB25: 3.12 | AC25: 50 | AD25: 2300
A26: 19 | B26: CMPale | C26: Regular | F26: KOHLER-350 | G26: 32 | H26: 4.35 | I26: 97.5 | J26: 1913 | M26: 4.09 | N26: 140 | R26: 0 | S26: 0 | W26: 4.54 | X26: 112.5 | AB26: 3.12 | AC26: 75
A27: 20 | B27: CMPLST | C27: Regular | F27: AKSA-100 | G27: 13.65 | H27: 0 | I27: 0 | J27: 2837.5 | M27: 0 | N27: 0 | O27: 2678.75 | R27: 0 | S27: 0 | T27: 2678.75 | W27: =1+(4/60) -> 1.0666667 | X27: 9.1 | Y27: 2360.25 | AB27: 0 | AC27: 0 | AD27: 2360.25
A28: 21 | B28: CMPLST | C28: Regular | F28: KOHLER-550 | G28: 59.15 | H28: =2+(56/60) -> 2.9333333 | I28: 95.05 | M28: =1+(42/60) -> 1.7 | N28: 36.4 | R28: 0.98 | S28: 31.85 | W28: =14+(3/60) -> 14.05 | X28: 341.25 | AB28: =2+(23/60) -> 2.3833333 | AC28: 68.25
A29: 22 | B29: CMSDHG | C29: Regular | F29: KOHLER-440 | G29: 54 | H29: 5.91 | I29: 268.45 | J29: 3355.3 | M29: 7.36 | N29: 349.75 | O29: 3005.55 | R29: 12.28 | S29: 359.45 | T29: 2555.1 | W29: 9.25 | X29: 353.9 | Y29: 2201.2 | AB29: 5.01 | AC29: 95.55 | AD29: 2105.65
A30: 23 | B30: CMSDHG | C30: Regular | F30: KOHLER-440 | G30: 59
A31: 24 | B31: CMSPT | C31: Regular | F31: KOHLER-440 | G31: 59.1 | H31: 3.9 | I31: 181.84 | J31: 2650.018 | M31: 8.4 | N31: 390.884 | O31: 2259.134 | R31: 6.4 | S31: 277.282 | T31: 2981.852 | W31: 4 | X31: 254.54 | Y31: 2727.312 | AB31: 6.01 | AC31: 222.73 | AD31: 2504.528
A32: 25 | B32: CMTLKK | C32: Regular | F32: KOHLER-275 | G32: 25 | H32: 0 | I32: 0 | J32: 4800 | M32: 0 | N32: 0 | O32: 4590 | R32: 0 | T32: 4300 | Y32: 3900 | AD32: 3550
A33: 26 | B33: CMTLKK | C33: Regular | F33: KOHLER-410 | G33: 60 | H33: =7+(37/60) -> 7.6166667 | I33: 340 | M33: =6+(15/60) -> 6.25 | N33: 320 | R33: =7+(59/60) -> 7.9833333 | S33: 290 | W33: =8+(47/60) -> 8.7833333 | X33: 300 | AB33: =10+(29/60) -> 10.483333 | AC33: 350
A34: 27 | B34: CMTM | C34: Regular | F34: VPS-500 | G34: 73 | H34: 0.7 | I34: 47 | J34: 1667 | M34: 1.02 | N34: 52 | O34: 2460 | R34: 0 | S34: 0 | T34: 2452 | W34: =2+(0.25/60) -> 2.0041667 | X34: 164 | Y34: 2673 | AB34: =2+(11/60) -> 2.1833333 | AC34: 145 | AD34: 2528
A35: 28 | B35: CMTM | C35: Regular | F35: SDMO-550 | G35: 60 | H35: 0 | I35: 0 | M35: 1.22 | N35: 70 | R35: 0 | S35: 0 | W35: 0 | X35: 0 | AB35: 0 | AC35: 0
A36: 29 | B36: CMWZYD | C36: Regular | F36: KHOLER-550 | G36: 81.828 | H36: =5+(37/60) -> 5.6166667 | I36: 272.7 | J36: 2181.78 | M36: =5+(41/60) -> 5.6833333 | N36: 295.31 | O36: 1886.47 | R36: =7+(43/60) -> 7.7166667 | S36: 227.228 | T36: 2572.868 | W36: =8+(22/60) -> 8.3666667 | X36: 472.784 | Y36: 2100.084 | AB36: 0 | AC36: 0 | AD36: 3100
A37: 30 | B37: CMYK | C37: Regular | F37: KOHLER-440 | G37: 59 | H37: =1+24/60 -> 1.4 | I37: 141 | J37: 1619 | M37: =1+(24/60) -> 1.4 | N37: 86 | O37: 1533 | R37: =0+(51/60) -> 0.85 | S37: 32 | T37: 1501 | W37: =9+(10/60) -> 9.1666667 | X37: 246 | Y37: 1255 | AB37: =5+(8/60) -> 5.1333333 | AC37: 95 | AD37: 1160
A38: 31 | B38: MPGV | C38: Regular | F38: KOHLER-440 | G38: 45 | H38: =0+(35/60) -> 0.58333333 | I38: 22.73 | J38: 4777.654 | M38: =1+(32/60) -> 1.5333333 | N38: 68.19 | O38: 5209.464 | R38: 0 | S38: 0 | T38: 5209 | W38: 0 | X38: 0 | Y38: 5209 | AB38: 0 | AC38: 0 | AD38: 5209
A39: 32 | B39: MPGV | C39: Regular | F39: KOHLER-727 | G39: 105 | H39: =0+(35/60) -> 0.58333333 | I39: 68.046 | M39: 0 | N39: 0 | R39: 0 | S39: 0 | W39: 0 | X39: 0 | AB39: 0 | AC39: 0
A40: 33 | B40: CMCNTP | C40: LNG | F40: KOHLER-550 | G40: 68 | H40: 0 | I40: 0 | J40: 1955 | M40: =1+(59/60) -> 1.9833333 | N40: 55 | O40: 1900 | R40: =3+(6/60) -> 3.1 | S40: 118 | T40: 1782 | W40: 0 | X40: 0 | Y40: 1782 | AB40: 0 | AC40: 0 | AD40: 1782
A41: 34 | B41: CMLHTY | C41: LNG | F41: KOHLER-550 | G41: 18 | H41: 0 | I41: 0 | J41: 7577 | M41: 0 | N41: 0 | O41: 7561 | R41: 0 | S41: 0 | T41: 7538 | W41: 0 | X41: 0 | Y41: 7538 | AB41: =0+(34/60) -> 0.56666667 | AC41: 22 | AD41: 7468
...

Sheet Day of Buffer
D2: ='diesel used'!C2 -> Type (Regular/ LNG) | J2: ='diesel used'!H2 -> 46106 | K2: ='diesel used'!H2 -> 46106 | L2: ='diesel used'!H2 -> 46106 | M2: ='diesel used'!H2 -> 46106 | O2: ='diesel used'!M2 -> 46107 | P2: ='diesel used'!M2 -> 46107 | Q2: ='diesel used'!M2 -> 46107 | R2: ='diesel used'!M2 -> 46107 | T2: ='diesel used'!R2 -> 46108 | U2: ='diesel used'!R2 -> 46108 | V2: ='diesel used'!R2 -> 46108 | W2: ='diesel used'!R2 -> 46108 | Y2: ='diesel used'!W2 -> 46109 | Z2: ='diesel used'!W2 -> 46109 | AA2: ='diesel used'!W2 -> 46109 | AB2: ='diesel used'!W2 -> 46109 | AD2: ='diesel used'!AB2 -> 46110 | AE2: ='diesel used'!AB2 -> 46110 | AF2: ='diesel used'!AB2 -> 46110 | AG2: ='diesel used'!AB2 -> 46110 | AI2: ='diesel used'!AG2 -> 0 | AJ2: ='diesel used'!AG2 -> 0 | AK2: ='diesel used'!AG2 -> 0 | AL2: ='diesel used'!AG2 -> 0
A3: ='diesel used'!A2 -> စဥ် | C3: ='diesel used'!B2 -> Center Name | H3: ='diesel used'!F3 -> KVA | K3: Daily Used (L) | L3: Diesel Balance | M3: Days of buffer | P3: Daily Used (L) | Q3: Diesel Balance | R3: Days of buffer | U3: Daily Used (L) | V3: Diesel Balance | W3: Days of buffer | Z3: Daily Used (L) | AA3: Diesel Balance | AB3: Days of buffer | AE3: Daily Used (L) | AF3: Diesel Balance | AG3: Days of buffer | AJ3: Daily Used (L) | AK3: Diesel Balance | AL3: Days of buffer
B4: CP | C4: Total | D4: Total | K4: =SUM(K8:K60) -> 3167.67 | L4: =SUM(L8:L60) -> 105745.8 | M4: =IFERROR(L4/K4, "X") -> 33.382835 | P4: =SUM(P8:P60) -> 3743.306 | Q4: =SUM(Q8:Q60) -> 109298.62 | R4: =IFERROR(Q4/P4, "X") -> 29.198419 | U4: =SUM(U8:U60) -> 2335.81 | V4: =SUM(V8:V60) -> 111773.36 | W4: =IFERROR(V4/U4, "X") -> 47.852077 | Z4: =SUM(Z8:Z60) -> 5129.414 | AA4: =SUM(AA8:AA60) -> 107605.8 | AB4: =IFERROR(AA4/Z4, "X") -> 20.978185 | AE4: =SUM(AE8:AE60) -> 2340.082 | AF4: =SUM(AF8:AF60) -> 101978.83 | AG4: =IFERROR(AF4/AE4, "X") -> 43.579168 | AJ4: =SUM(AJ8:AJ60) -> 0 | AK4: =SUM(AK8:AK60) -> 0 | AL4: =IFERROR(AK4/AJ4, "X") -> X
B5: CMHL | K5: =SUM(K62:K109) -> 2162.246 | L5: =SUM(L62:L109) -> 54413.31 | M5: =L5/K5 -> 25.16518 | P5: =SUM(P62:P109) -> 2189.272 | Q5: =SUM(Q62:Q109) -> 56063.672 | R5: =Q5/P5 -> 25.608363 | U5: =SUM(U62:U109) -> 1212.524 | V5: =SUM(V62:V109) -> 55808.262 | W5: =V5/U5 -> 46.026522 | Z5: =SUM(Z62:Z109) -> 3049.723 | AA5: =SUM(AA62:AA109) -> 58307.3 | AB5: =AA5/Z5 -> 19.118884 | AE5: =SUM(AE62:AE109) -> 1718.719 | AF5: =SUM(AF62:AF109) -> 58482.84 | AG5: =AF5/AE5 -> 34.026993 | AJ5: =SUM(AJ62:AJ109) -> 0 | AK5: =SUM(AK62:AK109) -> 0 | AL5: =AK5/AJ5 -> #DIV/0!
A8: ='diesel used'!A8 -> 1 | B8: CP | C8: ='diesel used'!B8 -> CM19 | D8: ='diesel used'!C8 -> Regular | H8: =RIGHT('diesel used'!F8, LEN('diesel used'!F8) - FIND("-", 'diesel used'!F8)) -> 550 | K8: ='diesel used'!I8+'diesel used'!I9+'diesel used'!I10 -> 105 | L8: ='diesel used'!J8 -> 2924 | M8: =IFERROR(L8/K8, "X") -> 27.847619 | P8: ='diesel used'!N8+'diesel used'!N9+'diesel used'!N10 -> 263 | Q8: ='diesel used'!O8 -> 2661 | R8: =IFERROR(Q8/P8, "X") -> 10.117871 | U8: ='diesel used'!S8+'diesel used'!S9+'diesel used'!S10 -> 95 | V8: ='diesel used'!T8 -> 4566 | W8: =IFERROR(V8/U8, "X") -> 48.063158 | Z8: ='diesel used'!X8+'diesel used'!X9+'diesel used'!X10 -> 51 | AA8: ='diesel used'!Y8 -> 5515 | AB8: =IFERROR(AA8/Z8, "X") -> 108.13725 | AE8: ='diesel used'!AC8+'diesel used'!AC9+'diesel used'!AC10 -> 185 | AF8: ='diesel used'!AD8 -> 5330 | AG8: =IFERROR(AF8/AE8, "X") -> 28.810811 | AJ8: ='diesel used'!AH8+'diesel used'!AH9+'diesel used'!AH10 -> 0 | AK8: ='diesel used'!AI8 -> 0 | AL8: =IFERROR(AK8/AJ8, "X") -> X
A9: ='diesel used'!A9 -> 2 | B9: CP | C9: ='diesel used'!B9 -> CM19 | D9: ='diesel used'!C9 -> Regular | H9: =RIGHT('diesel used'!F9, LEN('diesel used'!F9) - FIND("-", 'diesel used'!F9)) -> 150
A10: ='diesel used'!A10 -> 3 | B10: CP | C10: ='diesel used'!B10 -> CM19 | D10: ='diesel used'!C10 -> Regular | H10: =RIGHT('diesel used'!F10, LEN('diesel used'!F10) - FIND("-", 'diesel used'!F10)) -> 300
A11: ='diesel used'!A11 -> 4 | B11: CP | C11: ='diesel used'!B11 -> CMAYW | D11: ='diesel used'!C11 -> Regular | H11: =RIGHT('diesel used'!F11, LEN('diesel used'!F11) - FIND("-", 'diesel used'!F11)) -> 440 | K11: ='diesel used'!I11 -> 22 | L11: ='diesel used'!J11 -> 2146 | M11: =IFERROR(L11/K11, "X") -> 97.545455 | P11: ='diesel used'!N11 -> 192 | Q11: ='diesel used'!O11 -> 2954 | R11: =IFERROR(Q11/P11, "X") -> 15.385417 | U11: ='diesel used'!S11 -> 90 | V11: ='diesel used'!T11 -> 2864 | W11: =IFERROR(V11/U11, "X") -> 31.822222 | Z11: ='diesel used'!X11 -> 378 | AA11: ='diesel used'!Y11 -> 2486 | AB11: =IFERROR(AA11/Z11, "X") -> 6.5767196 | AE11: ='diesel used'!AC11 -> 159 | AF11: ='diesel used'!AD11 -> 2327 | AG11: =IFERROR(AF11/AE11, "X") -> 14.63522 | AJ11: ='diesel used'!AH11 -> 0 | AK11: ='diesel used'!AI11 -> 0 | AL11: =IFERROR(AK11/AJ11, "X") -> X
A12: ='diesel used'!A12 -> 5 | B12: CP | C12: ='diesel used'!B12 -> CMDGSK | D12: ='diesel used'!C12 -> Regular | H12: =RIGHT('diesel used'!F12, LEN('diesel used'!F12) - FIND("-", 'diesel used'!F12)) -> 550 | K12: ='diesel used'!I12 -> 309 | L12: ='diesel used'!J12 -> 6809 | M12: =IFERROR(L12/K12, "X") -> 22.035599 | P12: ='diesel used'!N12 -> 373 | Q12: ='diesel used'!O12 -> 6418 | R12: =IFERROR(Q12/P12, "X") -> 17.206434 | U12: ='diesel used'!S12 -> 418 | V12: ='diesel used'!T12 -> 6100 | W12: =IFERROR(V12/U12, "X") -> 14.593301 | Z12: ='diesel used'!X12 -> 386 | AA12: ='diesel used'!Y12 -> 5786 | AB12: =IFERROR(AA12/Z12, "X") -> 14.989637 | AE12: ='diesel used'!AC12 -> 205 | AF12: ='diesel used'!AD12 -> 5409 | AG12: =IFERROR(AF12/AE12, "X") -> 26.385366 | AJ12: ='diesel used'!AH12 -> 0 | AK12: ='diesel used'!AI12 -> 0 | AL12: =IFERROR(AK12/AJ12, "X") -> X
A13: ='diesel used'!A13 -> 6 | B13: CP | C13: ='diesel used'!B13 -> CMKSM | D13: ='diesel used'!C13 -> Regular | H13: =RIGHT('diesel used'!F13, LEN('diesel used'!F13) - FIND("-", 'diesel used'!F13)) -> 100 | K13: ='diesel used'!I13+'diesel used'!I14+'diesel used'!I15 -> 0 | L13: ='diesel used'!J13 -> 0 | M13: =IFERROR(L13/K13, "X") -> X | P13: ='diesel used'!N13+'diesel used'!N14+'diesel used'!N15 -> 45.46 | Q13: ='diesel used'!O13 -> 3041.01 | R13: =IFERROR(Q13/P13, "X") -> 66.894193 | U13: ='diesel used'!S13+'diesel used'!S14+'diesel used'!S15 -> 0 | V13: ='diesel used'!T13 -> 2995.55 | W13: =IFERROR(V13/U13, "X") -> X | Z13: ='diesel used'!X13+'diesel used'!X14+'diesel used'!X15 -> 68.19 | AA13: ='diesel used'!Y13 -> 2927.36 | AB13: =IFERROR(AA13/Z13, "X") -> 42.929462 | AE13: ='diesel used'!AC13+'diesel used'!AC14+'diesel used'!AC15 -> 54.552 | AF13: ='diesel used'!AD13 -> 2872.808 | AG13: =IFERROR(AF13/AE13, "X") -> 52.661827 | AJ13: ='diesel used'!AH13+'diesel used'!AH14+'diesel used'!AH15 -> 0 | AK13: ='diesel used'!AI13 -> 0 | AL13: =IFERROR(AK13/AJ13, "X") -> X
A14: ='diesel used'!A14 -> 7 | B14: CP | C14: ='diesel used'!B14 -> CMKSM | D14: ='diesel used'!C14 -> Regular | H14: =RIGHT('diesel used'!F14, LEN('diesel used'!F14) - FIND("-", 'diesel used'!F14)) -> 350
A15: ='diesel used'!A15 -> 8 | B15: CP | C15: ='diesel used'!B15 -> CMKSM | D15: ='diesel used'!C15 -> Regular | H15: =RIGHT('diesel used'!F15, LEN('diesel used'!F15) - FIND("-", 'diesel used'!F15)) -> 275
A16: ='diesel used'!A16 -> 9 | B16: CP | C16: ='diesel used'!B16 -> CMLNP | D16: ='diesel used'!C16 -> Regular | H16: =RIGHT('diesel used'!F16, LEN('diesel used'!F16) - FIND("-", 'diesel used'!F16)) -> 500 | K16: ='diesel used'!I16+'diesel used'!I17 -> 0 | L16: ='diesel used'!J16 -> 3145.712 | M16: =IFERROR(L16/K16, "X") -> X | P16: ='diesel used'!N16+'diesel used'!N17 -> 218.076 | Q16: ='diesel used'!O16 -> 5027.636 | R16: =IFERROR(Q16/P16, "X") -> 23.054513 | U16: ='diesel used'!S16+'diesel used'!S17 -> 0 | V16: ='diesel used'!T16 -> 5027.636 | W16: =IFERROR(V16/U16, "X") -> X | Z16: ='diesel used'!X16+'diesel used'!X17 -> 0 | AA16: ='diesel used'!Y16 -> 5027.636 | AB16: =IFERROR(AA16/Z16, "X") -> X | AE16: ='diesel used'!AC16+'diesel used'!AC17 -> 0 | AF16: ='diesel used'!AD16 -> 5027.636 | AG16: =IFERROR(AF16/AE16, "X") -> X | AJ16: ='diesel used'!AH16+'diesel used'!AH17 -> 0 | AK16: ='diesel used'!AI16 -> 0 | AL16: =IFERROR(AK16/AJ16, "X") -> X
A17: ='diesel used'!A17 -> 10 | B17: CP | C17: ='diesel used'!B17 -> CMLNP | D17: ='diesel used'!C17 -> Regular | H17: =RIGHT('diesel used'!F17, LEN('diesel used'!F17) - FIND("-", 'diesel used'!F17)) -> 500
A18: ='diesel used'!A18 -> 12 | B18: CP | C18: ='diesel used'!B18 -> CMLPZD | D18: ='diesel used'!C18 -> Regular | H18: =RIGHT('diesel used'!F18, LEN('diesel used'!F18) - FIND("-", 'diesel used'!F18)) -> 500 | K18: ='diesel used'!I18+'diesel used'!I19+'diesel used'!I20 -> 296 | L18: ='diesel used'!J18 -> 4501 | M18: =IFERROR(L18/K18, "X") -> 15.206081 | P18: ='diesel used'!N18+'diesel used'!N19+'diesel used'!N20 -> 186 | Q18: ='diesel used'!O18 -> 4700 | R18: =IFERROR(Q18/P18, "X") -> 25.268817 | U18: ='diesel used'!S18+'diesel used'!S19+'diesel used'!S20 -> 78 | V18: ='diesel used'!T18 -> 4610 | W18: =IFERROR(V18/U18, "X") -> 59.102564 | Z18: ='diesel used'!X18+'diesel used'!X19+'diesel used'!X20 -> 577 | AA18: ='diesel used'!Y18 -> 4182 | AB18: =IFERROR(AA18/Z18, "X") -> 7.2478336 | AE18: ='diesel used'!AC18+'diesel used'!AC19+'diesel used'!AC20 -> 213 | AF18: ='diesel used'!AD18 -> 3787 | AG18: =IFERROR(AF18/AE18, "X") -> 17.779343 | AJ18: ='diesel used'!AH18+'diesel used'!AH19+'diesel used'!AH20 -> 0 | AK18: ='diesel used'!AI18 -> 0 | AL18: =IFERROR(AK18/AJ18, "X") -> X
A19: ='diesel used'!A19 -> 11 | B19: CP | C19: ='diesel used'!B19 -> CMLPZD | D19: ='diesel used'!C19 -> Regular | H19: =RIGHT('diesel used'!F19, LEN('diesel used'!F19) - FIND("-", 'diesel used'!F19)) -> 550 | L19: ='diesel used'!J19 -> 4387 | Q19: ='diesel used'!O19 -> 4655 | V19: ='diesel used'!T19 -> 4577 | AA19: ='diesel used'!Y19 -> 4000 | AF19: ='diesel used'!AD19 -> 0 | AK19: ='diesel used'!AI19 -> 0
A20: ='diesel used'!A20 -> 13 | B20: CP | C20: ='diesel used'!B20 -> CMLPZD | D20: ='diesel used'!C20 -> Regular | H20: =RIGHT('diesel used'!F20, LEN('diesel used'!F20) - FIND("-", 'diesel used'!F20)) -> 700 | L20: ='diesel used'!J20 -> 0 | Q20: ='diesel used'!O20 -> 0 | V20: ='diesel used'!T20 -> 0 | AA20: ='diesel used'!Y20 -> 0 | AF20: ='diesel used'!AD20 -> 0 | AK20: ='diesel used'!AI20 -> 0
A21: ='diesel used'!A21 -> 14 | B21: CP | C21: ='diesel used'!B21 -> CMLSPL | D21: ='diesel used'!C21 -> Regular | H21: =RIGHT('diesel used'!F21, LEN('diesel used'!F21) - FIND("-", 'diesel used'!F21)) -> 200 | K21: ='diesel used'!I21+'diesel used'!I22+'diesel used'!I23 -> 527 | L21: ='diesel used'!J21 -> 0 | M21: =IFERROR(L21/K21, "X") -> 0 | P21: ='diesel used'!N21+'diesel used'!N22+'diesel used'!N23 -> 386 | Q21: ='diesel used'!O21 -> 0 | R21: =IFERROR(Q21/P21, "X") -> 0 | U21: ='diesel used'!S21+'diesel used'!S22+'diesel used'!S23 -> 296 | V21: ='diesel used'!T21 -> 5041 | W21: =IFERROR(V21/U21, "X") -> 17.030405 | Z21: ='diesel used'!X21+'diesel used'!X22+'diesel used'!X23 -> 1183 | AA21: ='diesel used'!Y21 -> 3858 | AB21: =IFERROR(AA21/Z21, "X") -> 3.2612003 | AE21: ='diesel used'!AC21+'diesel used'!AC22+'diesel used'!AC23 -> 103 | AF21: ='diesel used'!AD21 -> 3755 | AG21: =IFERROR(AF21/AE21, "X") -> 36.456311 | AJ21: ='diesel used'!AH21+'diesel used'!AH22+'diesel used'!AH23 -> 0 | AK21: ='diesel used'!AI21 -> 0 | AL21: =IFERROR(AK21/AJ21, "X") -> X
A22: ='diesel used'!A22 -> 15 | B22: CP | C22: ='diesel used'!B22 -> CMLSPL | D22: ='diesel used'!C22 -> Regular | H22: =RIGHT('diesel used'!F22, LEN('diesel used'!F22) - FIND("-", 'diesel used'!F22)) -> 727 | L22: ='diesel used'!J22 -> 0 | Q22: ='diesel used'!O22 -> 0 | V22: ='diesel used'!T22 -> 0 | AA22: ='diesel used'!Y22 -> 0 | AF22: ='diesel used'!AD22 -> 0 | AK22: ='diesel used'!AI22 -> 0
A23: ='diesel used'!A23 -> 16 | B23: CP | C23: ='diesel used'!B23 -> CMLSPL | D23: ='diesel used'!C23 -> Regular | H23: =RIGHT('diesel used'!F23, LEN('diesel used'!F23) - FIND("-", 'diesel used'!F23)) -> 500 | L23: ='diesel used'!J23 -> 4723 | Q23: ='diesel used'!O23 -> 5337 | V23: ='diesel used'!T23 -> 0 | AA23: ='diesel used'!Y23 -> 0 | AF23: ='diesel used'!AD23 -> 0 | AK23: ='diesel used'!AI23 -> 0
A24: ='diesel used'!A24 -> 17 | B24: CP | C24: ='diesel used'!B24 -> CMMNG | D24: ='diesel used'!C24 -> Regular | H24: =RIGHT('diesel used'!F24, LEN('diesel used'!F24) - FIND("-", 'diesel used'!F24)) -> 700 | K24: ='diesel used'!I24 -> 136.308 | L24: ='diesel used'!J24 -> 2627.42 | M24: =IFERROR(L24/K24, "X") -> 19.275611 | P24: ='diesel used'!N24 -> 72.736 | Q24: ='diesel used'!O24 -> 2554.684 | R24: =IFERROR(Q24/P24, "X") -> 35.12269 | U24: ='diesel used'!S24 -> 0 | V24: ='diesel used'!T24 -> 2554.684 | W24: =IFERROR(V24/U24, "X") -> X | Z24: ='diesel used'!X24 -> 113.65 | AA24: ='diesel used'!Y24 -> 2441.034 | AB24: =IFERROR(AA24/Z24, "X") -> 21.478522 | AE24: ='diesel used'!AC24 -> 0 | AF24: ='diesel used'!AD24 -> 2441.034 | AG24: =IFERROR(AF24/AE24, "X") -> X | AJ24: ='diesel used'!AH24 -> 0 | AK24: ='diesel used'!AI24 -> 0 | AL24: =IFERROR(AK24/AJ24, "X") -> X
A25: ='diesel used'!A25 -> 18 | B25: CP | C25: ='diesel used'!B25 -> CMPale | D25: ='diesel used'!C25 -> Regular | H25: =RIGHT('diesel used'!F25, LEN('diesel used'!F25) - FIND("-", 'diesel used'!F25)) -> 220 | K25: ='diesel used'!I25+'diesel used'!I26 -> 202.5 | L25: ='diesel used'!J25 -> 1912.5 | M25: =IFERROR(L25/K25, "X") -> 9.4444444 | P25: ='diesel used'!N25+'diesel used'!N26 -> 247.5 | Q25: ='diesel used'!O25 -> 1650 | R25: =IFERROR(Q25/P25, "X") -> 6.6666667 | U25: ='diesel used'!S25+'diesel used'!S26 -> 0 | V25: ='diesel used'!T25 -> 2650 | W25: =IFERROR(V25/U25, "X") -> X | Z25: ='diesel used'!X25+'diesel used'!X26 -> 225 | AA25: ='diesel used'!Y25 -> 2425 | AB25: =IFERROR(AA25/Z25, "X") -> 10.777778 | AE25: ='diesel used'!AC25+'diesel used'!AC26 -> 125 | AF25: ='diesel used'!AD25 -> 2300 | AG25: =IFERROR(AF25/AE25, "X") -> 18.4 | AJ25: ='diesel used'!AH25+'diesel used'!AH26 -> 0 | AK25: ='diesel used'!AI25 -> 0 | AL25: =IFERROR(AK25/AJ25, "X") -> X
A26: ='diesel used'!A26 -> 19 | B26: CP | C26: ='diesel used'!B26 -> CMPale | D26: ='diesel used'!C26 -> Regular | H26: =RIGHT('diesel used'!F26, LEN('diesel used'!F26) - FIND("-", 'diesel used'!F26)) -> 350 | L26: ='diesel used'!J26 -> 1913 | Q26: ='diesel used'!O26 -> 0 | V26: ='diesel used'!T26 -> 0 | AA26: ='diesel used'!Y26 -> 0 | AF26: ='diesel used'!AD26 -> 0 | AK26: ='diesel used'!AI26 -> 0
A27: ='diesel used'!A27 -> 20 | B27: CP | C27: ='diesel used'!B27 -> CMPLST | D27: ='diesel used'!C27 -> Regular | H27: =RIGHT('diesel used'!F27, LEN('diesel used'!F27) - FIND("-", 'diesel used'!F27)) -> 100 | K27: ='diesel used'!I27+'diesel used'!I28 -> 95.05 | L27: ='diesel used'!J27 -> 2837.5 | M27: =IFERROR(L27/K27, "X") -> 29.852709 | P27: ='diesel used'!N27+'diesel used'!N28 -> 36.4 | Q27: ='diesel used'!O27 -> 2678.75 | R27: =IFERROR(Q27/P27, "X") -> 73.592033 | U27: ='diesel used'!S27+'diesel used'!S28 -> 31.85 | V27: ='diesel used'!T27 -> 2678.75 | W27: =IFERROR(V27/U27, "X") -> 84.105181 | Z27: ='diesel used'!X27+'diesel used'!X28 -> 350.35 | AA27: ='diesel used'!Y27 -> 2360.25 | AB27: =IFERROR(AA27/Z27, "X") -> 6.7368346 | AE27: ='diesel used'!AC27+'diesel used'!AC28 -> 68.25 | AF27: ='diesel used'!AD27 -> 2360.25 | AG27: =IFERROR(AF27/AE27, "X") -> 34.582418 | AJ27: ='diesel used'!AH27+'diesel used'!AH28 -> 0 | AK27: ='diesel used'!AI27 -> 0 | AL27: =IFERROR(AK27/AJ27, "X") -> X
A28: ='diesel used'!A28 -> 21 | B28: CP | C28: ='diesel used'!B28 -> CMPLST | D28: ='diesel used'!C28 -> Regular | H28: =RIGHT('diesel used'!F28, LEN('diesel used'!F28) - FIND("-", 'diesel used'!F28)) -> 550
A29: ='diesel used'!A29 -> 22 | B29: CP | C29: ='diesel used'!B29 -> CMSDHG | D29: ='diesel used'!C29 -> Regular | H29: =RIGHT('diesel used'!F29, LEN('diesel used'!F29) - FIND("-", 'diesel used'!F29)) -> 440 | K29: ='diesel used'!I29+'diesel used'!I30 -> 268.45 | L29: ='diesel used'!J29 -> 3355.3 | M29: =IFERROR(L29/K29, "X") -> 12.498789 | P29: ='diesel used'!N29+'diesel used'!N30 -> 349.75 | Q29: ='diesel used'!O29 -> 3005.55 | R29: =IFERROR(Q29/P29, "X") -> 8.5934239 | U29: ='diesel used'!S29+'diesel used'!S30 -> 359.45 | V29: ='diesel used'!T29 -> 2555.1 | W29: =IFERROR(V29/U29, "X") -> 7.10836 | Z29: ='diesel used'!X29+'diesel used'!X30 -> 353.9 | AA29: ='diesel used'!Y29 -> 2201.2 | AB29: =IFERROR(AA29/Z29, "X") -> 6.2198361 | AE29: ='diesel used'!AC29+'diesel used'!AC30 -> 95.55 | AF29: ='diesel used'!AD29 -> 2105.65 | AG29: =IFERROR(AF29/AE29, "X") -> 22.037153 | AJ29: ='diesel used'!AH29+'diesel used'!AH30 -> 0 | AK29: ='diesel used'!AI29 -> 0 | AL29: =IFERROR(AK29/AJ29, "X") -> X
A30: ='diesel used'!A30 -> 23 | B30: CP | C30: ='diesel used'!B30 -> CMSDHG | D30: ='diesel used'!C30 -> Regular | H30: =RIGHT('diesel used'!F30, LEN('diesel used'!F30) - FIND("-", 'diesel used'!F30)) -> 440
A31: ='diesel used'!A31 -> 24 | B31: CP | C31: ='diesel used'!B31 -> CMSPT | D31: ='diesel used'!C31 -> Regular | H31: =RIGHT('diesel used'!F31, LEN('diesel used'!F31) - FIND("-", 'diesel used'!F31)) -> 440 | K31: ='diesel used'!I31 -> 181.84 | L31: ='diesel used'!J31 -> 2650.018 | M31: =IFERROR(L31/K31, "X") -> 14.57335 | P31: ='diesel used'!N31 -> 390.884 | Q31: ='diesel used'!O31 -> 2259.134 | R31: =IFERROR(Q31/P31, "X") -> 5.779551 | U31: ='diesel used'!S31 -> 277.282 | V31: ='diesel used'!T31 -> 2981.852 | W31: =IFERROR(V31/U31, "X") -> 10.753861 | Z31: ='diesel used'!X31 -> 254.54 | AA31: ='diesel used'!Y31 -> 2727.312 | AB31: =IFERROR(AA31/Z31, "X") -> 10.71467 | AE31: ='diesel used'!AC31 -> 222.73 | AF31: ='diesel used'!AD31 -> 2504.528 | AG31: =IFERROR(AF31/AE31, "X") -> 11.244682 | AJ31: ='diesel used'!AH31 -> 0 | AK31: ='diesel used'!AI31 -> 0 | AL31: =IFERROR(AK31/AJ31, "X") -> X
A32: ='diesel used'!A32 -> 25 | B32: CP | C32: ='diesel used'!B32 -> CMTLKK | D32: ='diesel used'!C32 -> Regular | H32: =RIGHT('diesel used'!F32, LEN('diesel used'!F32) - FIND("-", 'diesel used'!F32)) -> 275 | K32: ='diesel used'!I32+'diesel used'!I33 -> 340 | L32: ='diesel used'!J32 -> 4800 | M32: =IFERROR(L32/K32, "X") -> 14.117647 | P32: ='diesel used'!N32+'diesel used'!N33 -> 320 | Q32: ='diesel used'!O32 -> 4590 | R32: =IFERROR(Q32/P32, "X") -> 14.34375 | U32: ='diesel used'!S32+'diesel used'!S33 -> 290 | V32: ='diesel used'!T32 -> 4300 | W32: =IFERROR(V32/U32, "X") -> 14.827586 | Z32: ='diesel used'!X32+'diesel used'!X33 -> 300 | AA32: ='diesel used'!Y32 -> 3900 | AB32: =IFERROR(AA32/Z32, "X") -> 13 | AE32: ='diesel used'!AC32+'diesel used'!AC33 -> 350 | AF32: ='diesel used'!AD32 -> 3550 | AG32: =IFERROR(AF32/AE32, "X") -> 10.142857 | AJ32: ='diesel used'!AH32+'diesel used'!AH33 -> 0 | AK32: ='diesel used'!AI32 -> 0 | AL32: =IFERROR(AK32/AJ32, "X") -> X
A33: ='diesel used'!A33 -> 26 | B33: CP | C33: ='diesel used'!B33 -> CMTLKK | D33: ='diesel used'!C33 -> Regular | H33: =RIGHT('diesel used'!F33, LEN('diesel used'!F33) - FIND("-", 'diesel used'!F33)) -> 410 | L33: ='diesel used'!J33 -> 0 | Q33: ='diesel used'!O33 -> 0 | V33: ='diesel used'!T33 -> 0 | AA33: ='diesel used'!Y33 -> 0 | AF33: ='diesel used'!AD33 -> 0 | AK33: ='diesel used'!AI33 -> 0
A34: ='diesel used'!A34 -> 27 | B34: CP | C34: ='diesel used'!B34 -> CMTM | D34: ='diesel used'!C34 -> Regular | H34: =RIGHT('diesel used'!F34, LEN('diesel used'!F34) - FIND("-", 'diesel used'!F34)) -> 500 | K34: ='diesel used'!I34+'diesel used'!I35 -> 47 | L34: ='diesel used'!J34 -> 1667 | M34: =IFERROR(L34/K34, "X") -> 35.468085 | P34: ='diesel used'!N34+'diesel used'!N35 -> 122 | Q34: ='diesel used'!O34 -> 2460 | R34: =IFERROR(Q34/P34, "X") -> 20.163934 | U34: ='diesel used'!S34+'diesel used'!S35 -> 0 | V34: ='diesel used'!T34 -> 2452 | W34: =IFERROR(V34/U34, "X") -> X | Z34: ='diesel used'!X34+'diesel used'!X35 -> 164 | AA34: ='diesel used'!Y34 -> 2673 | AB34: =IFERROR(AA34/Z34, "X") -> 16.29878 | AE34: ='diesel used'!AC34+'diesel used'!AC35 -> 145 | AF34: ='diesel used'!AD34 -> 2528 | AG34: =IFERROR(AF34/AE34, "X") -> 17.434483 | AJ34: ='diesel used'!AH34+'diesel used'!AH35 -> 0 | AK34: ='diesel used'!AI34 -> 0 | AL34: =IFERROR(AK34/AJ34, "X") -> X
A35: ='diesel used'!A35 -> 28 | B35: CP | C35: ='diesel used'!B35 -> CMTM | D35: ='diesel used'!C35 -> Regular | H35: =RIGHT('diesel used'!F35, LEN('diesel used'!F35) - FIND("-", 'diesel used'!F35)) -> 550 | L35: ='diesel used'!J35 -> 0 | Q35: ='diesel used'!O35 -> 0 | V35: ='diesel used'!T35 -> 0 | AA35: ='diesel used'!Y35 -> 0 | AF35: ='diesel used'!AD35 -> 0 | AK35: ='diesel used'!AI35 -> 0
A36: ='diesel used'!A36 -> 29 | B36: CP | C36: ='diesel used'!B36 -> CMWZYD | D36: ='diesel used'!C36 -> Regular | H36: =RIGHT('diesel used'!F36, LEN('diesel used'!F36) - FIND("-", 'diesel used'!F36)) -> 550 | K36: ='diesel used'!I36 -> 272.7 | L36: ='diesel used'!J36 -> 2181.78 | M36: =IFERROR(L36/K36, "X") -> 8.0006601 | P36: ='diesel used'!N36 -> 295.31 | Q36: ='diesel used'!O36 -> 1886.47 | R36: =IFERROR(Q36/P36, "X") -> 6.3881006 | U36: ='diesel used'!S36 -> 227.228 | V36: ='diesel used'!T36 -> 2572.868 | W36: =IFERROR(V36/U36, "X") -> 11.322848 | Z36: ='diesel used'!X36 -> 472.784 | AA36: ='diesel used'!Y36 -> 2100.084 | AB36: =IFERROR(AA36/Z36, "X") -> 4.4419524 | AE36: ='diesel used'!AC36 -> 0 | AF36: ='diesel used'!AD36 -> 3100 | AG36: =IFERROR(AF36/AE36, "X") -> X | AJ36: ='diesel used'!AH36 -> 0 | AK36: ='diesel used'!AI36 -> 0 | AL36: =IFERROR(AK36/AJ36, "X") -> X
A37: ='diesel used'!A37 -> 30 | B37: CP | C37: ='diesel used'!B37 -> CMYK | D37: ='diesel used'!C37 -> Regular | H37: =RIGHT('diesel used'!F37, LEN('diesel used'!F37) - FIND("-", 'diesel used'!F37)) -> 440 | K37: ='diesel used'!I37 -> 141 | L37: ='diesel used'!J37 -> 1619 | M37: =IFERROR(L37/K37, "X") -> 11.48227 | P37: ='diesel used'!N37 -> 86 | Q37: ='diesel used'!O37 -> 1533 | R37: =IFERROR(Q37/P37, "X") -> 17.825581 | U37: ='diesel used'!S37 -> 32 | V37: ='diesel used'!T37 -> 1501 | W37: =IFERROR(V37/U37, "X") -> 46.90625 | Z37: ='diesel used'!X37 -> 246 | AA37: ='diesel used'!Y37 -> 1255 | AB37: =IFERROR(AA37/Z37, "X") -> 5.101626 | AE37: ='diesel used'!AC37 -> 95 | AF37: ='diesel used'!AD37 -> 1160 | AG37: =IFERROR(AF37/AE37, "X") -> 12.210526 | AJ37: ='diesel used'!AH37 -> 0 | AK37: ='diesel used'!AI37 -> 0 | AL37: =IFERROR(AK37/AJ37, "X") -> X
A38: ='diesel used'!A38 -> 31 | B38: CP | C38: ='diesel used'!B38 -> MPGV | D38: ='diesel used'!C38 -> Regular | H38: =RIGHT('diesel used'!F38, LEN('diesel used'!F38) - FIND("-", 'diesel used'!F38)) -> 440 | K38: ='diesel used'!I38+'diesel used'!I39 -> 90.776 | L38: ='diesel used'!J38 -> 4777.654 | M38: =IFERROR(L38/K38, "X") -> 52.631246 | P38: ='diesel used'!N38+'diesel used'!N39 -> 68.19 | Q38: ='diesel used'!O38 -> 5209.464 | R38: =IFERROR(Q38/P38, "X") -> 76.396304 | U38: ='diesel used'!S38+'diesel used'!S39 -> 0 | V38: ='diesel used'!T38 -> 5209 | W38: =IFERROR(V38/U38, "X") -> X | Z38: ='diesel used'!X38+'diesel used'!X39 -> 0 | AA38: ='diesel used'!Y38 -> 5209 | AB38: =IFERROR(AA38/Z38, "X") -> X | AE38: ='diesel used'!AC38+'diesel used'!AC39 -> 0 | AF38: ='diesel used'!AD38 -> 5209 | AG38: =IFERROR(AF38/AE38, "X") -> X | AJ38: ='diesel used'!AH38+'diesel used'!AH39 -> 0 | AK38: ='diesel used'!AI38 -> 0 | AL38: =IFERROR(AK38/AJ38, "X") -> X
A39: ='diesel used'!A39 -> 32 | B39: CP | C39: ='diesel used'!B39 -> MPGV | D39: ='diesel used'!C39 -> Regular | H39: =RIGHT('diesel used'!F39, LEN('diesel used'!F39) - FIND("-", 'diesel used'!F39)) -> 727 | K39: ='diesel used'!I39 -> 68.046 | L39: ='diesel used'!J39 -> 0 | P39: ='diesel used'!N39 -> 0 | Q39: ='diesel used'!O39 -> 0 | U39: ='diesel used'!S39 -> 0 | V39: ='diesel used'!T39 -> 0 | Z39: ='diesel used'!X39 -> 0 | AA39: ='diesel used'!Y39 -> 0 | AE39: ='diesel used'!AC39 -> 0 | AF39: ='diesel used'!AD39 -> 0 | AJ39: ='diesel used'!AH39 -> 0 | AK39: ='diesel used'!AI39 -> 0
A40: ='diesel used'!A40 -> 33 | B40: CP | C40: ='diesel used'!B40 -> CMCNTP | D40: ='diesel used'!C40 -> LNG | H40: =RIGHT('diesel used'!F40, LEN('diesel used'!F40) - FIND("-", 'diesel used'!F40)) -> 550 | K40: ='diesel used'!I40 -> 0 | L40: ='diesel used'!J40 -> 1955 | M40: =IFERROR(L40/K40, "X") -> X | P40: ='diesel used'!N40 -> 55 | Q40: ='diesel used'!O40 -> 1900 | R40: =IFERROR(Q40/P40, "X") -> 34.545455 | U40: ='diesel used'!S40 -> 118 | V40: ='diesel used'!T40 -> 1782 | W40: =IFERROR(V40/U40, "X") -> 15.101695 | Z40: ='diesel used'!X40 -> 0 | AA40: ='diesel used'!Y40 -> 1782 | AB40: =IFERROR(AA40/Z40, "X") -> X | AE40: ='diesel used'!AC40 -> 0 | AF40: ='diesel used'!AD40 -> 1782 | AG40: =IFERROR(AF40/AE40, "X") -> X | AJ40: ='diesel used'!AH40 -> 0 | AK40: ='diesel used'!AI40 -> 0 | AL40: =IFERROR(AK40/AJ40, "X") -> X
A41: ='diesel used'!A41 -> 34 | B41: CP | C41: ='diesel used'!B41 -> CMLHTY | D41: ='diesel used'!C41 -> LNG | H41: =RIGHT('diesel used'!F41, LEN('diesel used'!F41) - FIND("-", 'diesel used'!F41)) -> 550 | K41: ='diesel used'!I41+'diesel used'!I42+'diesel used'!I43 -> 65 | L41: ='diesel used'!J41 -> 7577 | M41: =IFERROR(L41/K41, "X") -> 116.56923 | P41: ='diesel used'!N41+'diesel used'!N42+'diesel used'!N43 -> 16 | Q41: ='diesel used'!O41 -> 7561 | R41: =IFERROR(Q41/P41, "X") -> 472.5625 | U41: ='diesel used'!S41+'diesel used'!S42+'diesel used'!S43 -> 23 | V41: ='diesel used'!T41 -> 7538 | W41: =IFERROR(V41/U41, "X") -> 327.73913 | Z41: ='diesel used'!X41+'diesel used'!X42+'diesel used'!X43 -> 0 | AA41: ='diesel used'!Y41 -> 7538 | AB41: =IFERROR(AA41/Z41, "X") -> X | AE41: ='diesel used'!AC41+'diesel used'!AC42+'diesel used'!AC43 -> 70 | AF41: ='diesel used'!AD41 -> 7468 | AG41: =IFERROR(AF41/AE41, "X") -> 106.68571 | AJ41: ='diesel used'!AH41+'diesel used'!AH42+'diesel used'!AH43 -> 0 | AK41: ='diesel used'!AI41 -> 0 | AL41: =IFERROR(AK41/AJ41, "X") -> X
A42: ='diesel used'!A42 -> 35 | B42: CP | C42: ='diesel used'!B42 -> CMLHTY | D42: ='diesel used'!C42 -> LNG | H42: =RIGHT('diesel used'!F42, LEN('diesel used'!F42) - FIND("-", 'diesel used'!F42)) -> 727
A43: ='diesel used'!A43 -> 36 | B43: CP | C43: ='diesel used'!B43 -> CMLHTY | D43: ='diesel used'!C43 -> LNG | H43: =RIGHT('diesel used'!F43, LEN('diesel used'!F43) - FIND("-", 'diesel used'!F43)) -> 200
...
